Workbook

Sheet Static Loads
A1: SES Case No. | B1: Description | C1: Angle from Horizontal | D1: Load | E1: Horizontal Load | F1: Vertical Load
A2: [-] | B2: [-] | C2: [deg] | D2: [kN] | E2: [kN] | F2: [kN]
A3: 1 | B3: Horizontal Driver | C3: 33.73 | D3: 760 | E3: =D3*COS(RADIANS(C3)) -> 632.06425 | F3: =D3*SIN(RADIANS(C3)) -> 422.01277
A4: 2 | B4: Vertical Driver | C4: 58.8 | D4: 760 | E4: =D4*COS(RADIANS(C4)) -> 393.70053 | F4: =D4*SIN(RADIANS(C4)) -> 650.07684
A5: 3 | B5: Max Peak of Both, Unfactored Design Case | C5: 45.8 | D5: 907 | E5: =D5*COS(RADIANS(C5)) -> 632.32875 | F5: =D5*SIN(RADIANS(C5)) -> 650.23792

Sheet Cyclic Loads
A3: Mooring Line Load Cycles over 20 years
B4: Cycle Mean (kN)
A5: Cycle Range (kN) | C5: Total Cycles | D5: 120 | E5: 150 | F5: 180 | G5: 210 | H5: 240 | I5: 270 | J5: 300 | K5: 330 | L5: 360 | M5: 390 | N5: 420 | O5: 450 | P5: 480 | Q5: 510 | R5: 540 | S5: 570 | T5: 600 | U5: 630 | V5: 660 | W5: 690 | X5: 720 | Y5: 750 | Z5: 780
B6: 20 | C6: =SUM(D6:Z6) -> 113175120 | D6: 0 | E6: 167840 | F6: 49731400 | G6: 13391520 | H6: 365920 | I6: 282000 | J6: 435800 | K6: 530880 | L6: 766440 | M6: 909280 | N6: 955720 | O6: 778560 | P6: 379640 | Q6: 371920 | R6: 236320 | S6: 223720 | T6: 139920 | U6: 2146640 | V6: 31984880 | W6: 9172040 | X6: 204560 | Y6: 120 | Z6: 0
B7: 40 | C7: =SUM(D7:Z7) -> 8992800 | D7: 0 | E7: 0 | F7: 162200 | G7: 373680 | H7: 75280 | I7: 130960 | J7: 89000 | K7: 242520 | L7: 380840 | M7: 576440 | N7: 389640 | O7: 290640 | P7: 213480 | Q7: 155000 | R7: 41160 | S7: 20720 | T7: 49080 | U7: 913120 | V7: 4227520 | W7: 647680 | X7: 13840 | Y7: 0 | Z7: 0
B8: 60 | C8: =SUM(D8:Z8) -> 2697360 | D8: 0 | E8: 0 | F8: 23320 | G8: 109760 | H8: 45480 | I8: 71760 | J8: 91440 | K8: 218520 | L8: 368360 | M8: 340560 | N8: 588720 | O8: 187720 | P8: 173520 | Q8: 65080 | R8: 62160 | S8: 66920 | T8: 13600 | U8: 102040 | V8: 153200 | W8: 14160 | X8: 1040 | Y8: 0 | Z8: 0
B9: 80 | C9: =SUM(D9:Z9) -> 2354480 | D9: 0 | E9: 0 | F9: 7400 | G9: 51440 | H9: 34160 | I9: 20200 | J9: 144120 | K9: 151000 | L9: 267360 | M9: 542760 | N9: 572680 | O9: 274080 | P9: 88680 | Q9: 105920 | R9: 19520 | S9: 5240 | T9: 5040 | U9: 25480 | V9: 37120 | W9: 2280 | X9: 0 | Y9: 0 | Z9: 0
B10: 100 | C10: =SUM(D10:Z10) -> 1779480 | D10: 0 | E10: 0 | F10: 40 | G10: 13360 | H10: 30360 | I10: 32400 | J10: 77600 | K10: 149880 | L10: 244480 | M10: 506040 | N10: 366040 | O10: 194800 | P10: 88840 | Q10: 34920 | R10: 26640 | S10: 2480 | T10: 1160 | U10: 7200 | V10: 3240 | W10: 0 | X10: 0 | Y10: 0 | Z10: 0
B11: 120 | C11: =SUM(D11:Z11) -> 1873720 | D11: 0 | E11: 0 | F11: 0 | G11: 0 | H11: 22240 | I11: 14800 | J11: 95440 | K11: 147600 | L11: 299200 | M11: 604200 | N11: 410840 | O11: 170680 | P11: 44600 | Q11: 33840 | R11: 3640 | S11: 8120 | T11: 13000 | U11: 4560 | V11: 880 | W11: 80 | X11: 0 | Y11: 0 | Z11: 0
B12: 140 | C12: =SUM(D12:Z12) -> 1909960 | D12: 0 | E12: 0 | F12: 0 | G12: 0 | H12: 23440 | I12: 27480 | J12: 81200 | K12: 134320 | L12: 211720 | M12: 716440 | N12: 428440 | O12: 133160 | P12: 97800 | Q12: 41920 | R12: 11640 | S12: 1680 | T12: 680 | U12: 40 | V12: 0 | W12: 0 | X12: 0 | Y12: 0 | Z12: 0
B13: 160 | C13: =SUM(D13:Z13) -> 1567120 | D13: 0 | E13: 0 | F13: 0 | G13: 0 | H13: 23360 | I13: 54520 | J13: 30560 | K13: 84360 | L13: 275200 | M13: 471880 | N13: 371080 | O13: 155240 | P13: 72520 | Q13: 15960 | R13: 7640 | S13: 3120 | T13: 1320 | U13: 360 | V13: 0 | W13: 0 | X13: 0 | Y13: 0 | Z13: 0
B14: 180 | C14: =SUM(D14:Z14) -> 1637440 | D14: 0 | E14: 0 | F14: 0 | G14: 0 | H14: 0 | I14: 13160 | J14: 60680 | K14: 55680 | L14: 203480 | M14: 591640 | N14: 482680 | O14: 114720 | P14: 55240 | Q14: 29360 | R14: 24760 | S14: 2520 | T14: 3520 | U14: 0 | V14: 0 | W14: 0 | X14: 0 | Y14: 0 | Z14: 0
B15: 200 | C15: =SUM(D15:Z15) -> 1907560 | D15: 0 | E15: 0 | F15: 0 | G15: 0 | H15: 0 | I15: 11000 | J15: 54080 | K15: 78880 | L15: 218440 | M15: 721240 | N15: 613280 | O15: 159160 | P15: 26360 | Q15: 6240 | R15: 6560 | S15: 11000 | T15: 1320 | U15: 0 | V15: 0 | W15: 0 | X15: 0 | Y15: 0 | Z15: 0
B16: 220 | C16: =SUM(D16:Z16) -> 1943520 | D16: 0 | E16: 0 | F16: 0 | G16: 0 | H16: 0 | I16: 3520 | J16: 49760 | K16: 64120 | L16: 278160 | M16: 778320 | N16: 567800 | O16: 165560 | P16: 19600 | Q16: 960 | R16: 8840 | S16: 6880 | T16: 0 | U16: 0 | V16: 0 | W16: 0 | X16: 0 | Y16: 0 | Z16: 0
B17: 240 | C17: =SUM(D17:Z17) -> 2191360 | D17: 0 | E17: 0 | F17: 0 | G17: 0 | H17: 0 | I17: 0 | J17: 70440 | K17: 106600 | L17: 260640 | M17: 982200 | N17: 666640 | O17: 79160 | P17: 13480 | Q17: 2120 | R17: 5520 | S17: 4520 | T17: 40 | U17: 0 | V17: 0 | W17: 0 | X17: 0 | Y17: 0 | Z17: 0
... B37: 640 | C37: =SUM(D37:Z37) -> 0 | D37: 0 | E37: 0 | F37: 0 | G37: 0 | H37: 0 | I37: 0 | J37: 0 | K37: 0 | L37: 0 | M37: 0 | N37: 0 | O37: 0 | P37: 0 | Q37: 0 | R37: 0 | S37: 0 | T37: 0 | U37: 0 | V37: 0 | W37: 0 | X37: 0 | Y37: 0 | Z37: 0
C40: min load | D40: 120 | E40: 150 | F40: 180 | G40: 210 | H40: 240 | I40: 270 | J40: 300 | K40: 330 | L40: 360 | M40: 390 | N40: 420 | O40: 450 | P40: 480 | Q40: 510 | R40: 540 | S40: 570 | T40: 600 | U40: 630 | V40: 660 | W40: 690 | X40: 720 | Y40: 750 | Z40: 780
B41: 20 | D41: =(D$40-$B41/2)*IF(D6=0,0,1) -> 0 | E41: =(E$40-$B41/2)*IF(E6=0,0,1) -> 140 | F41: =(F$40-$B41/2)*IF(F6=0,0,1) -> 170 | G41: =(G$40-$B41/2)*IF(G6=0,0,1) -> 200 | H41: =(H$40-$B41/2)*IF(H6=0,0,1) -> 230 | I41: =(I$40-$B41/2)*IF(I6=0,0,1) -> 260 | J41: =(J$40-$B41/2)*IF(J6=0,0,1) -> 290 | K41: =(K$40-$B41/2)*IF(K6=0,0,1) -> 320 | ... Z41: =(Z$40-$B41/2)*IF(Z6=0,0,1) -> 0
B42: 40 | D42: =(D$40-$B42/2)*IF(D7=0,0,1) -> 0 | E42: =(E$40-$B42/2)*IF(E7=0,0,1) -> 0 | F42: =(F$40-$B42/2)*IF(F7=0,0,1) -> 160 | G42: =(G$40-$B42/2)*IF(G7=0,0,1) -> 190 | H42: =(H$40-$B42/2)*IF(H7=0,0,1) -> 220 | I42: =(I$40-$B42/2)*IF(I7=0,0,1) -> 250 | J42: =(J$40-$B42/2)*IF(J7=0,0,1) -> 280 | K42: =(K$40-$B42/2)*IF(K7=0,0,1) -> 310 | ... Z42: =(Z$40-$B42/2)*IF(Z7=0,0,1) -> 0
B43: 60 | D43: =(D$40-$B43/2)*IF(D8=0,0,1) -> 0 | E43: =(E$40-$B43/2)*IF(E8=0,0,1) -> 0 | F43: =(F$40-$B43/2)*IF(F8=0,0,1) -> 150 | G43: =(G$40-$B43/2)*IF(G8=0,0,1) -> 180 | H43: =(H$40-$B43/2)*IF(H8=0,0,1) -> 210 | I43: =(I$40-$B43/2)*IF(I8=0,0,1) -> 240 | J43: =(J$40-$B43/2)*IF(J8=0,0,1) -> 270 | K43: =(K$40-$B43/2)*IF(K8=0,0,1) -> 300 | ... Z43: =(Z$40-$B43/2)*IF(Z8=0,0,1) -> 0
B44: 80 | D44: =(D$40-$B44/2)*IF(D9=0,0,1) -> 0 | E44: =(E$40-$B44/2)*IF(E9=0,0,1) -> 0 | F44: =(F$40-$B44/2)*IF(F9=0,0,1) -> 140 | G44: =(G$40-$B44/2)*IF(G9=0,0,1) -> 170 | H44: =(H$40-$B44/2)*IF(H9=0,0,1) -> 200 | I44: =(I$40-$B44/2)*IF(I9=0,0,1) -> 230 | J44: =(J$40-$B44/2)*IF(J9=0,0,1) -> 260 | K44: =(K$40-$B44/2)*IF(K9=0,0,1) -> 290 | ... Z44: =(Z$40-$B44/2)*IF(Z9=0,0,1) -> 0
B45: 100 | D45: =(D$40-$B45/2)*IF(D10=0,0,1) -> 0 | E45: =(E$40-$B45/2)*IF(E10=0,0,1) -> 0 | F45: =(F$40-$B45/2)*IF(F10=0,0,1) -> 130 | G45: =(G$40-$B45/2)*IF(G10=0,0,1) -> 160 | H45: =(H$40-$B45/2)*IF(H10=0,0,1) -> 190 | I45: =(I$40-$B45/2)*IF(I10=0,0,1) -> 220 | J45: =(J$40-$B45/2)*IF(J10=0,0,1) -> 250 | K45: =(K$40-$B45/2)*IF(K10=0,0,1) -> 280 | ... Z45: =(Z$40-$B45/2)*IF(Z10=0,0,1) -> 0
B46: 120 | D46: =(D$40-$B46/2)*IF(D11=0,0,1) -> 0 | E46: =(E$40-$B46/2)*IF(E11=0,0,1) -> 0 | F46: =(F$40-$B46/2)*IF(F11=0,0,1) -> 0 | G46: =(G$40-$B46/2)*IF(G11=0,0,1) -> 0 | H46: =(H$40-$B46/2)*IF(H11=0,0,1) -> 180 | I46: =(I$40-$B46/2)*IF(I11=0,0,1) -> 210 | J46: =(J$40-$B46/2)*IF(J11=0,0,1) -> 240 | K46: =(K$40-$B46/2)*IF(K11=0,0,1) -> 270 | ... Z46: =(Z$40-$B46/2)*IF(Z11=0,0,1) -> 0
B47: 140 | D47: =(D$40-$B47/2)*IF(D12=0,0,1) -> 0 | E47: =(E$40-$B47/2)*IF(E12=0,0,1) -> 0 | F47: =(F$40-$B47/2)*IF(F12=0,0,1) -> 0 | G47: =(G$40-$B47/2)*IF(G12=0,0,1) -> 0 | H47: =(H$40-$B47/2)*IF(H12=0,0,1) -> 170 | I47: =(I$40-$B47/2)*IF(I12=0,0,1) -> 200 | J47: =(J$40-$B47/2)*IF(J12=0,0,1) -> 230 | K47: =(K$40-$B47/2)*IF(K12=0,0,1) -> 260 | ... Z47: =(Z$40-$B47/2)*IF(Z12=0,0,1) -> 0
B48: 160 | D48: =(D$40-$B48/2)*IF(D13=0,0,1) -> 0 | E48: =(E$40-$B48/2)*IF(E13=0,0,1) -> 0 | F48: =(F$40-$B48/2)*IF(F13=0,0,1) -> 0 | G48: =(G$40-$B48/2)*IF(G13=0,0,1) -> 0 | H48: =(H$40-$B48/2)*IF(H13=0,0,1) -> 160 | I48: =(I$40-$B48/2)*IF(I13=0,0,1) -> 190 | J48: =(J$40-$B48/2)*IF(J13=0,0,1) -> 220 | K48: =(K$40-$B48/2)*IF(K13=0,0,1) -> 250 | ... Z48: =(Z$40-$B48/2)*IF(Z13=0,0,1) -> 0
B49: 180 | D49: =(D$40-$B49/2)*IF(D14=0,0,1) -> 0 | E49: =(E$40-$B49/2)*IF(E14=0,0,1) -> 0 | F49: =(F$40-$B49/2)*IF(F14=0,0,1) -> 0 | G49: =(G$40-$B49/2)*IF(G14=0,0,1) -> 0 | H49: =(H$40-$B49/2)*IF(H14=0,0,1) -> 0 | I49: =(I$40-$B49/2)*IF(I14=0,0,1) -> 180 | J49: =(J$40-$B49/2)*IF(J14=0,0,1) -> 210 | K49: =(K$40-$B49/2)*IF(K14=0,0,1) -> 240 | ... Z49: =(Z$40-$B49/2)*IF(Z14=0,0,1) -> 0
B50: 200 | D50: =(D$40-$B50/2)*IF(D15=0,0,1) -> 0 | E50: =(E$40-$B50/2)*IF(E15=0,0,1) -> 0 | F50: =(F$40-$B50/2)*IF(F15=0,0,1) -> 0 | G50: =(G$40-$B50/2)*IF(G15=0,0,1) -> 0 | H50: =(H$40-$B50/2)*IF(H15=0,0,1) -> 0 | I50: =(I$40-$B50/2)*IF(I15=0,0,1) -> 170 | J50: =(J$40-$B50/2)*IF(J15=0,0,1) -> 200 | K50: =(K$40-$B50/2)*IF(K15=0,0,1) -> 230 | ... Z50: =(Z$40-$B50/2)*IF(Z15=0,0,1) -> 0
B51: 220 | D51: =(D$40-$B51/2)*IF(D16=0,0,1) -> 0 | E51: =(E$40-$B51/2)*IF(E16=0,0,1) -> 0 | F51: =(F$40-$B51/2)*IF(F16=0,0,1) -> 0 | G51: =(G$40-$B51/2)*IF(G16=0,0,1) -> 0 | H51: =(H$40-$B51/2)*IF(H16=0,0,1) -> 0 | I51: =(I$40-$B51/2)*IF(I16=0,0,1) -> 160 | J51: =(J$40-$B51/2)*IF(J16=0,0,1) -> 190 | K51: =(K$40-$B51/2)*IF(K16=0,0,1) -> 220 | ... Z51: =(Z$40-$B51/2)*IF(Z16=0,0,1) -> 0
B52: 240 | D52: =(D$40-$B52/2)*IF(D17=0,0,1) -> 0 | E52: =(E$40-$B52/2)*IF(E17=0,0,1) -> 0 | F52: =(F$40-$B52/2)*IF(F17=0,0,1) -> 0 | G52: =(G$40-$B52/2)*IF(G17=0,0,1) -> 0 | H52: =(H$40-$B52/2)*IF(H17=0,0,1) -> 0 | I52: =(I$40-$B52/2)*IF(I17=0,0,1) -> 0 | J52: =(J$40-$B52/2)*IF(J17=0,0,1) -> 180 | K52: =(K$40-$B52/2)*IF(K17=0,0,1) -> 210 | ... Z52: =(Z$40-$B52/2)*IF(Z17=0,0,1) -> 0
... B72: 640 | D72: =(D$40-$B72/2)*IF(D37=0,0,1) -> 0 | E72: =(E$40-$B72/2)*IF(E37=0,0,1) -> 0 | F72: =(F$40-$B72/2)*IF(F37=0,0,1) -> 0 | G72: =(G$40-$B72/2)*IF(G37=0,0,1) -> 0 | H72: =(H$40-$B72/2)*IF(H37=0,0,1) -> 0 | I72: =(I$40-$B72/2)*IF(I37=0,0,1) -> 0 | J72: =(J$40-$B72/2)*IF(J37=0,0,1) -> 0 | K72: =(K$40-$B72/2)*IF(K37=0,0,1) -> 0 | ... Z72: =(Z$40-$B72/2)*IF(Z37=0,0,1) -> 0
C74: max load | D74: 120 | E74: 150 | F74: 180 | G74: 210 | H74: 240 | I74: 270 | J74: 300 | K74: 330 | L74: 360 | M74: 390 | N74: 420 | O74: 450 | P74: 480 | Q74: 510 | R74: 540 | S74: 570 | T74: 600 | U74: 630 | V74: 660 | W74: 690 | X74: 720 | Y74: 750 | Z74: 780
B75: 20 | D75: =(D$74+$B75/2)*IF(D6=0,0,1) -> 0 | E75: =(E$74+$B75/2)*IF(E6=0,0,1) -> 160 | F75: =(F$74+$B75/2)*IF(F6=0,0,1) -> 190 | G75: =(G$74+$B75/2)*IF(G6=0,0,1) -> 220 | H75: =(H$74+$B75/2)*IF(H6=0,0,1) -> 250 | I75: =(I$74+$B75/2)*IF(I6=0,0,1) -> 280 | J75: =(J$74+$B75/2)*IF(J6=0,0,1) -> 310 | K75: =(K$74+$B75/2)*IF(K6=0,0,1) -> 340 | ... Z75: =(Z$74+$B75/2)*IF(Z6=0,0,1) -> 0
B76: 40 | D76: =(D$74+$B76/2)*IF(D7=0,0,1) -> 0 | E76: =(E$74+$B76/2)*IF(E7=0,0,1) -> 0 | F76: =(F$74+$B76/2)*IF(F7=0,0,1) -> 200 | G76: =(G$74+$B76/2)*IF(G7=0,0,1) -> 230 | H76: =(H$74+$B76/2)*IF(H7=0,0,1) -> 260 | I76: =(I$74+$B76/2)*IF(I7=0,0,1) -> 290 | J76: =(J$74+$B76/2)*IF(J7=0,0,1) -> 320 | K76: =(K$74+$B76/2)*IF(K7=0,0,1) -> 350 | ... Z76: =(Z$74+$B76/2)*IF(Z7=0,0,1) -> 0
B77: 60 | D77: =(D$74+$B77/2)*IF(D8=0,0,1) -> 0 | E77: =(E$74+$B77/2)*IF(E8=0,0,1) -> 0 | F77: =(F$74+$B77/2)*IF(F8=0,0,1) -> 210 | G77: =(G$74+$B77/2)*IF(G8=0,0,1) -> 240 | H77: =(H$74+$B77/2)*IF(H8=0,0,1) -> 270 | I77: =(I$74+$B77/2)*IF(I8=0,0,1) -> 300 | J77: =(J$74+$B77/2)*IF(J8=0,0,1) -> 330 | K77: =(K$74+$B77/2)*IF(K8=0,0,1) -> 360 | ... Z77: =(Z$74+$B77/2)*IF(Z8=0,0,1) -> 0
B78: 80 | D78: =(D$74+$B78/2)*IF(D9=0,0,1) -> 0 | E78: =(E$74+$B78/2)*IF(E9=0,0,1) -> 0 | F78: =(F$74+$B78/2)*IF(F9=0,0,1) -> 220 | G78: =(G$74+$B78/2)*IF(G9=0,0,1) -> 250 | H78: =(H$74+$B78/2)*IF(H9=0,0,1) -> 280 | I78: =(I$74+$B78/2)*IF(I9=0,0,1) -> 310 | J78: =(J$74+$B78/2)*IF(J9=0,0,1) -> 340 | K78: =(K$74+$B78/2)*IF(K9=0,0,1) -> 370 | ... Z78: =(Z$74+$B78/2)*IF(Z9=0,0,1) -> 0
B79: 100 | D79: =(D$74+$B79/2)*IF(D10=0,0,1) -> 0 | E79: =(E$74+$B79/2)*IF(E10=0,0,1) -> 0 | F79: =(F$74+$B79/2)*IF(F10=0,0,1) -> 230 | G79: =(G$74+$B79/2)*IF(G10=0,0,1) -> 260 | H79: =(H$74+$B79/2)*IF(H10=0,0,1) -> 290 | I79: =(I$74+$B79/2)*IF(I10=0,0,1) -> 320 | J79: =(J$74+$B79/2)*IF(J10=0,0,1) -> 350 | K79: =(K$74+$B79/2)*IF(K10=0,0,1) -> 380 | ... Z79: =(Z$74+$B79/2)*IF(Z10=0,0,1) -> 0
B80: 120 | D80: =(D$74+$B80/2)*IF(D11=0,0,1) -> 0 | E80: =(E$74+$B80/2)*IF(E11=0,0,1) -> 0 | F80: =(F$74+$B80/2)*IF(F11=0,0,1) -> 0 | G80: =(G$74+$B80/2)*IF(G11=0,0,1) -> 0 | H80: =(H$74+$B80/2)*IF(H11=0,0,1) -> 300 | I80: =(I$74+$B80/2)*IF(I11=0,0,1) -> 330 | J80: =(J$74+$B80/2)*IF(J11=0,0,1) -> 360 | K80: =(K$74+$B80/2)*IF(K11=0,0,1) -> 390 | ... Z80: =(Z$74+$B80/2)*IF(Z11=0,0,1) -> 0
B81: 140 | D81: =(D$74+$B81/2)*IF(D12=0,0,1) -> 0 | E81: =(E$74+$B81/2)*IF(E12=0,0,1) -> 0 | F81: =(F$74+$B81/2)*IF(F12=0,0,1) -> 0 | G81: =(G$74+$B81/2)*IF(G12=0,0,1) -> 0 | H81: =(H$74+$B81/2)*IF(H12=0,0,1) -> 310 | I81: =(I$74+$B81/2)*IF(I12=0,0,1) -> 340 | J81: =(J$74+$B81/2)*IF(J12=0,0,1) -> 370 | K81: =(K$74+$B81/2)*IF(K12=0,0,1) -> 400 | ... Z81: =(Z$74+$B81/2)*IF(Z12=0,0,1) -> 0
B82: 160 | D82: =(D$74+$B82/2)*IF(D13=0,0,1) -> 0 | E82: =(E$74+$B82/2)*IF(E13=0,0,1) -> 0 | F82: =(F$74+$B82/2)*IF(F13=0,0,1) -> 0 | G82: =(G$74+$B82/2)*IF(G13=0,0,1) -> 0 | H82: =(H$74+$B82/2)*IF(H13=0,0,1) -> 320 | I82: =(I$74+$B82/2)*IF(I13=0,0,1) -> 350 | J82: =(J$74+$B82/2)*IF(J13=0,0,1) -> 380 | K82: =(K$74+$B82/2)*IF(K13=0,0,1) -> 410 | ... Z82: =(Z$74+$B82/2)*IF(Z13=0,0,1) -> 0
B83: 180 | D83: =(D$74+$B83/2)*IF(D14=0,0,1) -> 0 | E83: =(E$74+$B83/2)*IF(E14=0,0,1) -> 0 | F83: =(F$74+$B83/2)*IF(F14=0,0,1) -> 0 | G83: =(G$74+$B83/2)*IF(G14=0,0,1) -> 0 | H83: =(H$74+$B83/2)*IF(H14=0,0,1) -> 0 | I83: =(I$74+$B83/2)*IF(I14=0,0,1) -> 360 | J83: =(J$74+$B83/2)*IF(J14=0,0,1) -> 390 | K83: =(K$74+$B83/2)*IF(K14=0,0,1) -> 420 | ... Z83: =(Z$74+$B83/2)*IF(Z14=0,0,1) -> 0
...

Sheet Load-Disp
A1: Zones | D1: Structural Element
A2: Displacement (m) | B2: Load (kN) | D2: Displacement (m) | E2: Load (kN)
A3: 0 | B3: 0 | D3: 0 | E3: 0
A4: 0.00017223804 | B4: 9.9996 | D4: 0.00016484516 | E4: 10
A5: 0.0004091593 | B5: 19.9992 | D5: 0.0003833349 | E5: 20
A6: 0.00068968105 | B6: 29.9988 | D6: 0.00063799985 | E6: 30
A7: 0.001055416 | B7: 39.9984 | D7: 0.00092662601 | E7: 40
A8: 0.0014199443 | B8: 49.998 | D8: 0.0012470724 | E8: 50
A9: 0.0018166004 | B9: 59.9976 | D9: 0.0015830561 | E9: 60
A10: 0.0022333256 | B10: 69.9972 | D10: 0.0019475553 | E10: 70
A11: 0.0026743259 | B11: 79.9968 | D11: 0.0023352361 | E11: 80
A12: 0.0031307692 | B12: 89.9964 | D12: 0.0027321744 | E12: 90
A13: 0.0035987373 | B13: 99.996 | D13: 0.0031469002 | E13: 100
A14: 0.0040799112 | B14: 109.9956 | D14: 0.0035867667 | E14: 110
... A42: 0.020500051 | B42: 389.9844 | D42: 0.018808853 | E42: 390
D43: 0.019434404 | E43: 400
D44: 0.020063782 | E44: 410

Sheet Stress
C1: =Damage!E41 -> 936.51986 | D1: =Damage!F41 -> 1206.0621 | E1: =Damage!G41 -> 1135.4806 | F1: =Damage!H41 -> 589.06441 | G1: =Damage!I41 -> 411.19866 | H1: =Damage!J41 -> 533.46844
A2: Load applied (kN) | C2: {=TRANSPOSE('Static Loads'!D3:D5)} -> 760 | D2: 760 | E2: 907 | F2: =C2 -> 760 | G2: =D2 -> 760 | H2: =E2 -> 907
C3: Static case 1 | D3: Static case 2 | E3: Static case 3 | F3: Static case 1 | G3: Static case 2 | H3: Static case 3
A4: Cyclic Stress (MPa) | C4: =160.62 -> 160.62 | D4: 174.75 | E4: 204.4 | F4: 137.62 | G4: 122.08 | H4: 158.9
B5: Cyclic Load Range (kN) | C5: Hotspot 1 | D5: Hotspot 1 | E5: Hotspot 1 | F5: Hotspot 2 | G5: Hotspot 2 | H5: Hotspot 2
B6: ='Cyclic Loads'!B6 -> 20 | C6: =$B6/C$2*C$4 -> 4.2268421 | D6: =$B6/D$2*D$4 -> 4.5986842 | E6: =$B6/E$2*E$4 -> 4.5071665 | F6: =$B6/F$2*F$4 -> 3.6215789 | G6: =$B6/G$2*G$4 -> 3.2126316 | H6: =$B6/H$2*H$4 -> 3.5038589
B7: ='Cyclic Loads'!B7 -> 40 | C7: =$B7/C$2*C$4 -> 8.4536842 | D7: =$B7/D$2*D$4 -> 9.1973684 | E7: =$B7/E$2*E$4 -> 9.014333 | F7: =$B7/F$2*F$4 -> 7.2431579 | G7: =$B7/G$2*G$4 -> 6.4252632 | H7: =$B7/H$2*H$4 -> 7.0077178
B8: ='Cyclic Loads'!B8 -> 60 | C8: =$B8/C$2*C$4 -> 12.680526 | D8: =$B8/D$2*D$4 -> 13.796053 | E8: =$B8/E$2*E$4 -> 13.521499 | F8: =$B8/F$2*F$4 -> 10.864737 | G8: =$B8/G$2*G$4 -> 9.6378947 | H8: =$B8/H$2*H$4 -> 10.511577
B9: ='Cyclic Loads'!B9 -> 80 | C9: =$B9/C$2*C$4 -> 16.907368 | D9: =$B9/D$2*D$4 -> 18.394737 | E9: =$B9/E$2*E$4 -> 18.028666 | F9: =$B9/F$2*F$4 -> 14.486316 | G9: =$B9/G$2*G$4 -> 12.850526 | H9: =$B9/H$2*H$4 -> 14.015436
B10: ='Cyclic Loads'!B10 -> 100 | C10: =$B10/C$2*C$4 -> 21.134211 | D10: =$B10/D$2*D$4 -> 22.993421 | E10: =$B10/E$2*E$4 -> 22.535832 | F10: =$B10/F$2*F$4 -> 18.107895 | G10: =$B10/G$2*G$4 -> 16.063158 | H10: =$B10/H$2*H$4 -> 17.519294
B11: ='Cyclic Loads'!B11 -> 120 | C11: =$B11/C$2*C$4 -> 25.361053 | D11: =$B11/D$2*D$4 -> 27.592105 | E11: =$B11/E$2*E$4 -> 27.042999 | F11: =$B11/F$2*F$4 -> 21.729474 | G11: =$B11/G$2*G$4 -> 19.275789 | H11: =$B11/H$2*H$4 -> 21.023153
B12: ='Cyclic Loads'!B12 -> 140 | C12: =$B12/C$2*C$4 -> 29.587895 | D12: =$B12/D$2*D$4 -> 32.190789 | E12: =$B12/E$2*E$4 -> 31.550165 | F12: =$B12/F$2*F$4 -> 25.351053 | G12: =$B12/G$2*G$4 -> 22.488421 | H12: =$B12/H$2*H$4 -> 24.527012
B13: ='Cyclic Loads'!B13 -> 160 | C13: =$B13/C$2*C$4 -> 33.814737 | D13: =$B13/D$2*D$4 -> 36.789474 | E13: =$B13/E$2*E$4 -> 36.057332 | F13: =$B13/F$2*F$4 -> 28.972632 | G13: =$B13/G$2*G$4 -> 25.701053 | H13: =$B13/H$2*H$4 -> 28.030871
B14: ='Cyclic Loads'!B14 -> 180 | C14: =$B14/C$2*C$4 -> 38.041579 | D14: =$B14/D$2*D$4 -> 41.388158 | E14: =$B14/E$2*E$4 -> 40.564498 | F14: =$B14/F$2*F$4 -> 32.594211 | G14: =$B14/G$2*G$4 -> 28.913684 | H14: =$B14/H$2*H$4 -> 31.53473
B15: ='Cyclic Loads'!B15 -> 200 | C15: =$B15/C$2*C$4 -> 42.268421 | D15: =$B15/D$2*D$4 -> 45.986842 | E15: =$B15/E$2*E$4 -> 45.071665 | F15: =$B15/F$2*F$4 -> 36.215789 | G15: =$B15/G$2*G$4 -> 32.126316 | H15: =$B15/H$2*H$4 -> 35.038589
B16: ='Cyclic Loads'!B16 -> 220 | C16: =$B16/C$2*C$4 -> 46.495263 | D16: =$B16/D$2*D$4 -> 50.585526 | E16: =$B16/E$2*E$4 -> 49.578831 | F16: =$B16/F$2*F$4 -> 39.837368 | G16: =$B16/G$2*G$4 -> 35.338947 | H16: =$B16/H$2*H$4 -> 38.542448
B17: ='Cyclic Loads'!B17 -> 240 | C17: =$B17/C$2*C$4 -> 50.722105 | D17: =$B17/D$2*D$4 -> 55.184211 | E17: =$B17/E$2*E$4 -> 54.085998 | F17: =$B17/F$2*F$4 -> 43.458947 | G17: =$B17/G$2*G$4 -> 38.551579 | H17: =$B17/H$2*H$4 -> 42.046307
... B37: ='Cyclic Loads'!B37 -> 640 | C37: =$B37/C$2*C$4 -> 135.25895 | D37: =$B37/D$2*D$4 -> 147.15789 | E37: =$B37/E$2*E$4 -> 144.22933 | F37: =$B37/F$2*F$4 -> 115.89053 | G37: =$B37/G$2*G$4 -> 102.80421 | H37: =$B37/H$2*H$4 -> 112.12348

Sheet SCF
C1: SCF
B2: Cyclic Load Range (kN) | C2: Hotspot 1 | D2: Hotspot 1 | E2: Hotspot 1 | F2: Hotspot 2 | G2: Hotspot 2 | H2: Hotspot 2
B3: ='Cyclic Loads'!B6 -> 20 | C3: 1 | D3: 1 | E3: 1 | F3: 1 | G3: 1 | H3: 1
B4: ='Cyclic Loads'!B7 -> 40 | C4: 1 | D4: 1 | E4: 1 | F4: 1 | G4: 1 | H4: 1
B5: ='Cyclic Loads'!B8 -> 60 | C5: 1 | D5: 1 | E5: 1 | F5: 1 | G5: 1 | H5: 1
B6: ='Cyclic Loads'!B9 -> 80 | C6: 1 | D6: 1 | E6: 1 | F6: 1 | G6: 1 | H6: 1
B7: ='Cyclic Loads'!B10 -> 100 | C7: 1 | D7: 1 | E7: 1 | F7: 1 | G7: 1 | H7: 1
B8: ='Cyclic Loads'!B11 -> 120 | C8: 1 | D8: 1 | E8: 1 | F8: 1 | G8: 1 | H8: 1
B9: ='Cyclic Loads'!B12 -> 140 | C9: 1 | D9: 1 | E9: 1 | F9: 1 | G9: 1 | H9: 1
B10: ='Cyclic Loads'!B13 -> 160 | C10: 1 | D10: 1 | E10: 1 | F10: 1 | G10: 1 | H10: 1
B11: ='Cyclic Loads'!B14 -> 180 | C11: 1 | D11: 1 | E11: 1 | F11: 1 | G11: 1 | H11: 1
B12: ='Cyclic Loads'!B15 -> 200 | C12: 1 | D12: 1 | E12: 1 | F12: 1 | G12: 1 | H12: 1
B13: ='Cyclic Loads'!B16 -> 220 | C13: 1 | D13: 1 | E13: 1 | F13: 1 | G13: 1 | H13: 1
B14: ='Cyclic Loads'!B17 -> 240 | C14: 1 | D14: 1 | E14: 1 | F14: 1 | G14: 1 | H14: 1
... B34: ='Cyclic Loads'!B37 -> 640 | C34: 1 | D34: 1 | E34: 1 | F34: 1 | G34: 1 | H34: 1

Sheet Damage
D1: m | E1: 3
D2: log abar | E2: 10.57 | F2: abar | G2: =10^E2 -> 3.7153523e+10
D3: SCF | E3: 1
D4: t/t_ref | E4: 0.5
D5: k | E5: 0.25
B7: Cyclic Load Range (kN) | C7: No. of cycles | E7: Case 1 Hotspot 1 | F7: Case 2 Hotspot 1 | G7: Case 3 Hotspot 1 | H7: Case 1 Hotspot 2 | I7: Case 2 Hotspot 2 | J7: Case 3 Hotspot 2
B8: 20 | C8: ='Cyclic Loads'!C6 -> 113175120 | E8: =1/$G$2*$C8*(Stress!C6*SCF!C3*$E$4^$E$5)^$E$1 -> 0.13678124 | F8: =1/$G$2*$C8*(Stress!D6*SCF!D3*$E$4^$E$5)^$E$1 -> 0.17614861 | G8: =1/$G$2*$C8*(Stress!E6*SCF!E3*$E$4^$E$5)^$E$1 -> 0.16583999 | H8: =1/$G$2*$C8*(Stress!F6*SCF!F3*$E$4^$E$5)^$E$1 -> 0.08603444 | I8: =1/$G$2*$C8*(Stress!G6*SCF!G3*$E$4^$E$5)^$E$1 -> 0.060056669 | J8: =1/$G$2*$C8*(Stress!H6*SCF!H3*$E$4^$E$5)^$E$1 -> 0.077914499
B9: 40 | C9: ='Cyclic Loads'!C7 -> 8992800 | E9: =1/$G$2*$C9*(Stress!C7*SCF!C4*$E$4^$E$5)^$E$1 -> 0.086948181 | F9: =1/$G$2*$C9*(Stress!D7*SCF!D4*$E$4^$E$5)^$E$1 -> 0.11197297 | G9: =1/$G$2*$C9*(Stress!E7*SCF!E4*$E$4^$E$5)^$E$1 -> 0.10542005 | H9: =1/$G$2*$C9*(Stress!F7*SCF!F4*$E$4^$E$5)^$E$1 -> 0.054689795 | I9: =1/$G$2*$C9*(Stress!G7*SCF!G4*$E$4^$E$5)^$E$1 -> 0.03817642 | J9: =1/$G$2*$C9*(Stress!H7*SCF!H4*$E$4^$E$5)^$E$1 -> 0.049528166
B10: 60 | C10: ='Cyclic Loads'!C8 -> 2697360 | E10: =1/$G$2*$C10*(Stress!C8*SCF!C5*$E$4^$E$5)^$E$1 -> 0.08801937 | F10: =1/$G$2*$C10*(Stress!D8*SCF!D5*$E$4^$E$5)^$E$1 -> 0.11335246 | G10: =1/$G$2*$C10*(Stress!E8*SCF!E5*$E$4^$E$5)^$E$1 -> 0.10671881 | H10: =1/$G$2*$C10*(Stress!F8*SCF!F5*$E$4^$E$5)^$E$1 -> 0.055363565 | I10: =1/$G$2*$C10*(Stress!G8*SCF!G5*$E$4^$E$5)^$E$1 -> 0.038646748 | J10: =1/$G$2*$C10*(Stress!H8*SCF!H5*$E$4^$E$5)^$E$1 -> 0.050138345
B11: 80 | C11: ='Cyclic Loads'!C9 -> 2354480 | E11: =1/$G$2*$C11*(Stress!C9*SCF!C6*$E$4^$E$5)^$E$1 -> 0.18211703 | F11: =1/$G$2*$C11*(Stress!D9*SCF!D6*$E$4^$E$5)^$E$1 -> 0.23453262 | G11: =1/$G$2*$C11*(Stress!E9*SCF!E6*$E$4^$E$5)^$E$1 -> 0.22080723 | H11: =1/$G$2*$C11*(Stress!F9*SCF!F6*$E$4^$E$5)^$E$1 -> 0.11455033 | I11: =1/$G$2*$C11*(Stress!G9*SCF!G6*$E$4^$E$5)^$E$1 -> 0.079962296 | J11: =1/$G$2*$C11*(Stress!H9*SCF!H6*$E$4^$E$5)^$E$1 -> 0.10373906
B12: 100 | C12: ='Cyclic Loads'!C10 -> 1779480 | E12: =1/$G$2*$C12*(Stress!C10*SCF!C7*$E$4^$E$5)^$E$1 -> 0.2688306 | F12: =1/$G$2*$C12*(Stress!D10*SCF!D7*$E$4^$E$5)^$E$1 -> 0.34620345 | G12: =1/$G$2*$C12*(Stress!E10*SCF!E7*$E$4^$E$5)^$E$1 -> 0.32594283 | H12: =1/$G$2*$C12*(Stress!F10*SCF!F7*$E$4^$E$5)^$E$1 -> 0.16909256 | I12: =1/$G$2*$C12*(Stress!G10*SCF!G7*$E$4^$E$5)^$E$1 -> 0.11803571 | J12: =1/$G$2*$C12*(Stress!H10*SCF!H7*$E$4^$E$5)^$E$1 -> 0.15313358
B13: 120 | C13: ='Cyclic Loads'!C11 -> 1873720 | E13: =1/$G$2*$C13*(Stress!C11*SCF!C8*$E$4^$E$5)^$E$1 -> 0.48914095 | F13: =1/$G$2*$C13*(Stress!D11*SCF!D8*$E$4^$E$5)^$E$1 -> 0.6299219 | G13: =1/$G$2*$C13*(Stress!E11*SCF!E8*$E$4^$E$5)^$E$1 -> 0.59305742 | H13: =1/$G$2*$C13*(Stress!F11*SCF!F8*$E$4^$E$5)^$E$1 -> 0.30766622 | I13: =1/$G$2*$C13*(Stress!G11*SCF!G8*$E$4^$E$5)^$E$1 -> 0.21476758 | J13: =1/$G$2*$C13*(Stress!H11*SCF!H8*$E$4^$E$5)^$E$1 -> 0.27862865
B14: 140 | C14: ='Cyclic Loads'!C12 -> 1909960 | E14: =1/$G$2*$C14*(Stress!C12*SCF!C9*$E$4^$E$5)^$E$1 -> 0.79176075 | F14: =1/$G$2*$C14*(Stress!D12*SCF!D9*$E$4^$E$5)^$E$1 -> 1.0196395 | G14: =1/$G$2*$C14*(Stress!E12*SCF!E9*$E$4^$E$5)^$E$1 -> 0.95996787 | H14: =1/$G$2*$C14*(Stress!F12*SCF!F9*$E$4^$E$5)^$E$1 -> 0.49801195 | I14: =1/$G$2*$C14*(Stress!G12*SCF!G9*$E$4^$E$5)^$E$1 -> 0.34763914 | J14: =1/$G$2*$C14*(Stress!H12*SCF!H9*$E$4^$E$5)^$E$1 -> 0.45100952
B15: 160 | C15: ='Cyclic Loads'!C13 -> 1567120 | E15: =1/$G$2*$C15*(Stress!C13*SCF!C10*$E$4^$E$5)^$E$1 -> 0.96972321 | F15: =1/$G$2*$C15*(Stress!D13*SCF!D10*$E$4^$E$5)^$E$1 -> 1.2488218 | G15: =1/$G$2*$C15*(Stress!E13*SCF!E10*$E$4^$E$5)^$E$1 -> 1.1757379 | H15: =1/$G$2*$C15*(Stress!F13*SCF!F10*$E$4^$E$5)^$E$1 -> 0.60994909 | I15: =1/$G$2*$C15*(Stress!G13*SCF!G10*$E$4^$E$5)^$E$1 -> 0.42577729 | J15: =1/$G$2*$C15*(Stress!H13*SCF!H10*$E$4^$E$5)^$E$1 -> 0.55238202
B16: 180 | C16: ='Cyclic Loads'!C14 -> 1637440 | E16: =1/$G$2*$C16*(Stress!C14*SCF!C11*$E$4^$E$5)^$E$1 -> 1.442675 | F16: =1/$G$2*$C16*(Stress!D14*SCF!D11*$E$4^$E$5)^$E$1 -> 1.8578951 | G16: =1/$G$2*$C16*(Stress!E14*SCF!E11*$E$4^$E$5)^$E$1 -> 1.7491668 | H16: =1/$G$2*$C16*(Stress!F14*SCF!F11*$E$4^$E$5)^$E$1 -> 0.90743243 | I16: =1/$G$2*$C16*(Stress!G14*SCF!G11*$E$4^$E$5)^$E$1 -> 0.63343667 | J16: =1/$G$2*$C16*(Stress!H14*SCF!H11*$E$4^$E$5)^$E$1 -> 0.82178885
B17: 200 | C17: ='Cyclic Loads'!C15 -> 1907560 | E17: =1/$G$2*$C17*(Stress!C15*SCF!C12*$E$4^$E$5)^$E$1 -> 2.3054398 | F17: =1/$G$2*$C17*(Stress!D15*SCF!D12*$E$4^$E$5)^$E$1 -> 2.9689745 | G17: =1/$G$2*$C17*(Stress!E15*SCF!E12*$E$4^$E$5)^$E$1 -> 2.7952233 | H17: =1/$G$2*$C17*(Stress!F15*SCF!F12*$E$4^$E$5)^$E$1 -> 1.4501054 | I17: =1/$G$2*$C17*(Stress!G15*SCF!G12*$E$4^$E$5)^$E$1 -> 1.0122516 | J17: =1/$G$2*$C17*(Stress!H15*SCF!H12*$E$4^$E$5)^$E$1 -> 1.3132443
B18: 220 | C18: ='Cyclic Loads'!C16 -> 1943520 | E18: =1/$G$2*$C18*(Stress!C16*SCF!C13*$E$4^$E$5)^$E$1 -> 3.1263864 | F18: =1/$G$2*$C18*(Stress!D16*SCF!D13*$E$4^$E$5)^$E$1 -> 4.0261999 | G18: =1/$G$2*$C18*(Stress!E16*SCF!E13*$E$4^$E$5)^$E$1 -> 3.7905774 | H18: =1/$G$2*$C18*(Stress!F16*SCF!F13*$E$4^$E$5)^$E$1 -> 1.9664751 | I18: =1/$G$2*$C18*(Stress!G16*SCF!G13*$E$4^$E$5)^$E$1 -> 1.3727054 | J18: =1/$G$2*$C18*(Stress!H16*SCF!H13*$E$4^$E$5)^$E$1 -> 1.7808789
B19: 240 | C19: ='Cyclic Loads'!C17 -> 2191360 | E19: =1/$G$2*$C19*(Stress!C17*SCF!C14*$E$4^$E$5)^$E$1 -> 4.5764956 | F19: =1/$G$2*$C19*(Stress!D17*SCF!D14*$E$4^$E$5)^$E$1 -> 5.8936689 | G19: =1/$G$2*$C19*(Stress!E17*SCF!E14*$E$4^$E$5)^$E$1 -> 5.5487578 | H19: =1/$G$2*$C19*(Stress!F17*SCF!F14*$E$4^$E$5)^$E$1 -> 2.8785836 | I19: =1/$G$2*$C19*(Stress!G17*SCF!G14*$E$4^$E$5)^$E$1 -> 2.0094062 | J19: =1/$G$2*$C19*(Stress!H17*SCF!H14*$E$4^$E$5)^$E$1 -> 2.6069025
... B39: 640 | C39: ='Cyclic Loads'!C37 -> 0 | E39: =1/$G$2*$C39*(Stress!C37*SCF!C34*$E$4^$E$5)^$E$1 -> 0 | F39: =1/$G$2*$C39*(Stress!D37*SCF!D34*$E$4^$E$5)^$E$1 -> 0 | G39: =1/$G$2*$C39*(Stress!E37*SCF!E34*$E$4^$E$5)^$E$1 -> 0 | H39: =1/$G$2*$C39*(Stress!F37*SCF!F34*$E$4^$E$5)^$E$1 -> 0 | I39: =1/$G$2*$C39*(Stress!G37*SCF!G34*$E$4^$E$5)^$E$1 -> 0 | J39: =1/$G$2*$C39*(Stress!H37*SCF!H34*$E$4^$E$5)^$E$1 -> 0
C41: =SUM(C8:C39) -> 204358840 | E41: =SUM(E8:E39) -> 936.51986 | F41: =SUM(F8:F39) -> 1206.0621 | G41: =SUM(G8:G39) -> 1135.4806 | H41: =SUM(H8:H39) -> 589.06441 | I41: =SUM(I8:I39) -> 411.19866 | J41: =SUM(J8:J39) -> 533.46844
